{
  "id": "GHSA-f58w-649r-qjr9",
  "summary": "Moderate severity vulnerability that affects splunk-sdk",
  "details": "Splunk-SDK-Python before 1.6.6 does not properly verify untrusted TLS server certificates, which could result in man-in-the-middle attacks.",
  "aliases": [
    "CVE-2019-5729"
  ],
  "modified": "2023-02-16T23:09:32.620287Z",
  "published": "2019-03-25T16:18:04Z",
  "database_specific": {
    "cwe_ids": [
      "CWE-295"
    ],
    "severity": "HIGH",
    "github_reviewed": true,
    "github_reviewed_at": "2020-06-16T21:33:41Z",
    "nvd_published_at": null
  },
  "references": [
    {
      "type": "ADVISORY",
      "url": "https://nvd.nist.gov/vuln/detail/CVE-2019-5729"
    },
    {
      "type": "ADVISORY",
      "url": "https://github.com/advisories/GHSA-f58w-649r-qjr9"
    },
    {
      "type": "WEB",
      "url": "https://www.splunk.com/view/SP-CAAAQAD"
    }
  ],
  "affected": [
    {
      "package": {
        "name": "splunk-sdk",
        "ecosystem": "PyPI",
        "purl": "pkg:pypi/splunk-sdk"
      },
      "ranges": [
        {
          "type": "ECOSYSTEM",
          "events": [
            {
              "introduced": "0"
            },
            {
              "fixed": "1.6.6"
            }
          ]
        }
      ],
      "versions": [
        "0.1.0",
        "0.1.0a",
        "0.8.0",
        "1.0.0",
        "1.1.0",
        "1.2.0",
        "1.2.1",
        "1.2.2",
        "1.2.3",
        "1.3.0",
        "1.3.1",
        "1.4.0",
        "1.5.0",
        "1.6.0",
        "1.6.1",
        "1.6.2",
        "1.6.3",
        "1.6.4",
        "1.6.5"
      ],
      "database_specific": {
        "source": "https://github.com/github/advisory-database/blob/main/advisories/github-reviewed/2019/03/GHSA-f58w-649r-qjr9/GHSA-f58w-649r-qjr9.json"
      }
    }
  ],
  "schema_version": "1.3.0",
  "severity": [
    {
      "type": "CVSS_V3",
      "score": "CVSS:3.0/AV:N/AC:H/PR:N/UI:N/S:U/C:H/I:H/A:H"
    }
  ]
}