{
  "id": "PYSEC-2010-6",
  "details": "The ftp_QUIT function in ftpserver.py in pyftpdlib before 0.5.0 allows remote authenticated users to cause a denial of service (file descriptor exhaustion and daemon outage) by sending a QUIT command during a disallowed data-transfer attempt.",
  "aliases": [
    "CVE-2008-7264",
    "GHSA-8p2c-fghc-9hj4"
  ],
  "modified": "2021-07-05T00:01:24.722786Z",
  "published": "2010-10-19T20:00:00Z",
  "references": [
    {
      "type": "WEB",
      "url": "http://code.google.com/p/pyftpdlib/source/diff?spec=svn344&r=344&format=side&path=/trunk/pyftpdlib/ftpserver.py"
    },
    {
      "type": "WEB",
      "url": "http://code.google.com/p/pyftpdlib/issues/detail?id=71"
    },
    {
      "type": "WEB",
      "url": "http://code.google.com/p/pyftpdlib/source/browse/trunk/HISTORY"
    },
    {
      "type": "WEB",
      "url": "http://code.google.com/p/pyftpdlib/source/detail?r=344"
    },
    {
      "type": "ADVISORY",
      "url": "https://github.com/advisories/GHSA-8p2c-fghc-9hj4"
    }
  ],
  "affected": [
    {
      "package": {
        "name": "pyftpdlib",
        "ecosystem": "PyPI",
        "purl": "pkg:pypi/pyftpdlib"
      },
      "ranges": [
        {
          "type": "ECOSYSTEM",
          "events": [
            {
              "introduced": "0"
            },
            {
              "fixed": "0.5.0"
            }
          ]
        }
      ],
      "versions": [
        "0.2.0",
        "0.3.0",
        "0.4.0"
      ],
      "database_specific": {
        "source": "https://github.com/pypa/advisory-database/blob/main/vulns/pyftpdlib/PYSEC-2010-6.yaml"
      }
    }
  ],
  "schema_version": "1.3.0"
}